<?xml version="1.0" ?>
<mujoco model="ant">
  <compiler angle="degree" coordinate="local" inertiafromgeom="true"/>
  <option integrator="RK4" timestep="0.01"/>

  <custom>
    <!-- initial qpos (same as default Ant_v5) -->
    <numeric
      name="init_qpos"
      data="0.0 0.0 0.55 1.0 0.0 0.0 0.0 0.0 1.0 0.0 -1.0 0.0 -1.0 0.0 1.0"/>
  </custom>

  <default>
    <joint armature="1" damping="1" limited="true"/>
    <!-- We leave geom default contype=1 but conaffinity=0 here,
         and override contype/conaffinity individually below. -->
    <geom
      conaffinity="0"
      condim="3"
      density="5.0"
      friction="1 0.5 0.5"
      margin="0.01"
      rgba="0.8 0.6 0.4 1"/>
  </default>

  <asset>
    <texture
      builtin="gradient"
      height="100"
      rgb1="1 1 1"
      rgb2="0 0 0"
      type="skybox"
      width="100"/>
    <texture
      builtin="flat"
      height="1278"
      mark="cross"
      markrgb="1 1 1"
      name="texgeom"
      random="0.01"
      rgb1="0.8 0.6 0.4"
      rgb2="0.8 0.6 0.4"
      type="cube"
      width="127"/>
    <texture
      builtin="checker"
      height="100"
      name="texplane"
      rgb1="0 0 0"
      rgb2="0.8 0.8 0.8"
      type="2d"
      width="100"/>

    <material
      name="MatPlane"
      reflectance="0.5"
      shininess="1"
      specular="1"
      texrepeat="60 60"
      texture="texplane"/>
    <material
      name="geom"
      texture="texgeom"
      texuniform="true"/>
  </asset>

  <worldbody>
    <light
      cutoff="100"
      diffuse="1 1 1"
      dir="-0 0 -1.3"
      directional="true"
      exponent="1"
      pos="0 0 1.3"
      specular=".1 .1 .1"/>

    <!-- ─────────── THICK “LANDING” FOR x < 0  ───────────
         • spans x∈[–15, 5], y∈[–20,20], z∈[–0.01,0.01]
         • contype="1" conaffinity="1" to ensure it collides with the Ant’s geoms
    -->
    <geom
      name="landing"
      type="box"
      size="50 20 0.01"
      pos="-5 0 0.01"
      contype="1"
      conaffinity="1"
      material="MatPlane"
      friction="1 0.5 0.5"
      rgba="0.8 0.9 0.8 1"/>

    <!-- ─────────── ONLY NOW THE FIVE STEPS FOR x ≥ 0 ───────────
         Each step is (depth=0.5, width=40, height=0.25).
         We give each step contype="1" conaffinity="1" so collisions are enabled.
    -->
    <!-- STEP 1: spans x=[5.0…11], bottom at z=0.01, top at z=0.26 -->
    <geom
      name="step1"
      type="box"
      size="0.5 20 0.145"
      pos="2 0 0.155"
      contype="1"
      conaffinity="1"
      material="MatPlane"
      friction="1 0.5 0.5"
      rgba="0.7 0.7 0.7 1"/>

    <!-- STEP 2: spans x=[11…17], bottom at z=0.26, top at z=0.51 -->
    <!-- <geom
      name="step2"
      type="box"
      size="0.2 20 0.145"
      pos="8.5 0 0.155"
      contype="1"
      conaffinity="1"
      material="MatPlane"
      friction="1 0.5 0.5"
      rgba="0.7 0.7 0.7 1"/> -->

    <!-- STEP 3: spans x=[17…23], bottom at z=0.51, top at z=0.76 -->
    <!-- <geom
      name="step3"
      type="box"
      size="0.2 20 0.145"
      pos="13 0 0.155"
      contype="1"
      conaffinity="1"
      material="MatPlane"
      friction="1 0.5 0.5"
      rgba="0.7 0.7 0.7 1"/> -->

    <!-- STEP 4: spans x=[23…29], bottom at z=0.76, top at z=1.01 -->
    <!-- <geom
      name="step4"
      type="box"
      size="0.5 20 0.145"
      pos="17.5 0 0.155"
      contype="1"
      conaffinity="1"
      material="MatPlane"
      friction="1 0.5 0.5"
      rgba="0.7 0.7 0.7 1"/> -->

    <!-- STEP 5: spans x=[2.0…2.5], bottom at z=1.01, top at z=1.26 -->
    <!-- <geom
      name="step5"
      type="box"
      size="0.25 20 0.1559
      pos="2.25 0 1.205"
      contype="1"
      conaffinity="1"
      material="MatPlane"
      friction="1 0.5 0.5"
      rgba="0.7 0.7 0.7 1"/> -->

    <!-- ─────────── THE ANT’S BODY (capsules, joints, etc.) ─────────── -->
    <body name="torso" pos="0 0 0.75">
      <camera
        name="track"
        mode="trackcom"
        pos="0 -3 0.3"
        xyaxes="1 0 0 0 0 1"/>
      <geom
        name="torso_geom"
        pos="0 0 0"
        size="0.25"
        type="sphere"/>
      <joint
        armature="0"
        damping="0"
        limited="false"
        margin="0.01"
        name="root"
        pos="0 0 0"
        type="free"/>

      <!-- Front left leg -->
      <body name="front_left_leg" pos="0 0 0">
        <geom
          fromto="0.0 0.0 0.0 0.2 0.2 0.0"
          name="aux_1_geom"
          size="0.08"
          type="capsule"/>
        <body name="aux_1" pos="0.2 0.2 0">
          <joint
            axis="0 0 1"
            name="hip_1"
            pos="0.0 0.0 0.0"
            range="-30 30"
            type="hinge"/>
          <geom
            fromto="0.0 0.0 0.0 0.2 0.2 0.0"
            name="left_leg_geom"
            size="0.08"
            type="capsule"/>
          <body pos="0.2 0.2 0">
            <joint
              axis="-1 1 0"
              name="ankle_1"
              pos="0.0 0.0 0.0"
              range="30 70"
              type="hinge"/>
            <geom
              fromto="0.0 0.0 0.0 0.4 0.4 0.0"
              name="left_ankle_geom"
              size="0.08"
              type="capsule"/>
          </body>
        </body>
      </body>

      <!-- Front right leg -->
      <body name="front_right_leg" pos="0 0 0">
        <geom
          fromto="0.0 0.0 0.0 -0.2 0.2 0.0"
          name="aux_2_geom"
          size="0.08"
          type="capsule"/>
        <body name="aux_2" pos="-0.2 0.2 0">
          <joint
            axis="0 0 1"
            name="hip_2"
            pos="0.0 0.0 0.0"
            range="-30 30"
            type="hinge"/>
          <geom
            fromto="0.0 0.0 0.0 -0.2 0.2 0.0"
            name="right_leg_geom"
            size="0.08"
            type="capsule"/>
          <body pos="-0.2 0.2 0">
            <joint
              axis="1 1 0"
              name="ankle_2"
              pos="0.0 0.0 0.0"
              range="-70 -30"
              type="hinge"/>
            <geom
              fromto="0.0 0.0 0.0 -0.4 0.4 0.0"
              name="right_ankle_geom"
              size="0.08"
              type="capsule"/>
          </body>
        </body>
      </body>

      <!-- Back left leg -->
      <body name="back_leg" pos="0 0 0">
        <geom
          fromto="0.0 0.0 0.0 -0.2 -0.2 0.0"
          name="aux_3_geom"
          size="0.08"
          type="capsule"/>
        <body name="aux_3" pos="-0.2 -0.2 0">
          <joint
            axis="0 0 1"
            name="hip_3"
            pos="0.0 0.0 0.0"
            range="-30 30"
            type="hinge"/>
          <geom
            fromto="0.0 0.0 0.0 -0.2 -0.2 0.0"
            name="back_leg_geom"
            size="0.08"
            type="capsule"/>
          <body pos="-0.2 -0.2 0">
            <joint
              axis="-1 1 0"
              name="ankle_3"
              pos="0.0 0.0 0.0"
              range="-70 -30"
              type="hinge"/>
            <geom
              fromto="0.0 0.0 0.0 -0.4 -0.4 0.0"
              name="third_ankle_geom"
              size="0.08"
              type="capsule"/>
          </body>
        </body>
      </body>

      <!-- Back right leg -->
      <body name="right_back_leg" pos="0 0 0">
        <geom
          fromto="0.0 0.0 0.0 0.2 -0.2 0.0"
          name="aux_4_geom"
          size="0.08"
          type="capsule"/>
        <body name="aux_4" pos="0.2 -0.2 0">
          <joint
            axis="0 0 1"
            name="hip_4"
            pos="0.0 0.0 0.0"
            range="-30 30"
            type="hinge"/>
          <geom
            fromto="0.0 0.0 0.0 0.2 -0.2 0.0"
            name="rightback_leg_geom"
            size="0.08"
            type="capsule"/>
          <body pos="0.2 -0.2 0">
            <joint
              axis="1 1 0"
              name="ankle_4"
              pos="0.0 0.0 0.0"
              range="30 70"
              type="hinge"/>
            <geom
              fromto="0.0 0.0 0.0 0.4 -0.4 0.0"
              name="fourth_ankle_geom"
              size="0.08"
              type="capsule"/>
          </body>
        </body>
      </body>
    </body>
  </worldbody>

  <actuator>
    <motor ctrllimited="true" ctrlrange="-1.0 1.0" joint="hip_4" gear="150"/>
    <motor ctrllimited="true" ctrlrange="-1.0 1.0" joint="ankle_4" gear="150"/>
    <motor ctrllimited="true" ctrlrange="-1.0 1.0" joint="hip_1" gear="150"/>
    <motor ctrllimited="true" ctrlrange="-1.0 1.0" joint="ankle_1" gear="150"/>
    <motor ctrllimited="true" ctrlrange="-1.0 1.0" joint="hip_2" gear="150"/>
    <motor ctrllimited="true" ctrlrange="-1.0 1.0" joint="ankle_2" gear="150"/>
    <motor ctrllimited="true" ctrlrange="-1.0 1.0" joint="hip_3" gear="150"/>
    <motor ctrllimited="true" ctrlrange="-1.0 1.0" joint="ankle_3" gear="150"/>
  </actuator>
</mujoco>

